<?xml version="1.0" encoding="utf-8"?>
<!-- =================================================================================== -->
<!-- |    This document was autogenerated by xacro from spot.urdf.xacro                | -->
<!-- |    EDITING THIS FILE BY HAND IS NOT RECOMMENDED                                 | -->
<!-- =================================================================================== -->
<robot name="spot" xmlns:xacro="http://www.ros.org/wiki/xacro">
  <material name="orange">
    <color rgba="1.0 0.5 0.0 1" />
  </material>
  <material name="black">
    <color rgba="0.1 0.1 0.1 1" />
  </material>
  <material name="grey">
    <color rgba="0.6 0.6 0.6 1" />
  </material>

  <!-- Robot description -->
  <!-- STATIC Links -->
  <link name="base_link">
    <visual>
      <origin rpy="0 0 0" xyz="0 0 0" />
      <geometry>
        <box size="0.25 0.15 0.1" />
      </geometry>
      <material name="orange" />
    </visual>
    <collision>
      <origin rpy="0 0 1.57079632679" xyz="0 0 0" />
      <geometry>
        <box size="0.25 0.15 0.1" />
      </geometry>
    </collision>
    <inertial>
      <mass value="0.6" />
      <origin rpy="0 0 0" xyz="0 0 0" />
      <!-- Inertial Axes -->
      <inertia ixx="0.0025" ixy="0" ixz="0" iyx="0" iyy="0.0011498" iyz="0" izx="0" izy="0" izz="0.0026498" />
    </inertial>
  </link>

  <!-- m to mm -->
  <link name="front_bracket">
    <visual>
      <origin rpy="0 0 1.57079632679" xyz="0 0 0" />
      <geometry>
        <box size="0.15 0.05 0.1" />
      </geometry>
      <material name="black" />
    </visual>
    <collision>
      <origin rpy="0 0 1.57079632679" xyz="0 0 0" />
      <geometry>
        <box size="0.10 0.05 0.1" />
      </geometry>
    </collision>
    <inertial>
      <mass value="0.1" />
      <origin rpy="0 0 0" xyz="0 0 0" />
      <!-- Inertial Axes -->
      <inertia ixx="0.000107083333333" ixy="0" ixz="0" iyx="0" iyy="6.54166666667e-05" iyz="0" izx="0" izy="0" izz="5.20833333333e-05" />
    </inertial>
  </link>

  <!-- m to mm -->
  <link name="back_bracket">
    <visual>
      <origin rpy="0 0 1.57079632679" xyz="0 0 0" />
      <geometry>
        <box size="0.15 0.05 0.1" />
      </geometry>
      <material name="black" />
    </visual>
    <collision>
      <origin rpy="0 0 1.57079632679" xyz="0 0 0" />
      <geometry>
        <box size="0.15 0.05 0.1" />
      </geometry>
    </collision>
    <inertial>
      <mass value="0.1" />
      <origin rpy="0 0 0" xyz="0 0 0" />
      <!-- Inertial Axes -->
      <inertia ixx="0.000107083333333" ixy="0" ixz="0" iyx="0" iyy="6.54166666667e-05" iyz="0" izx="0" izy="0" izz="5.20833333333e-05" />
    </inertial>
  </link>

  <joint name="base_back_bracket" type="fixed">
    <origin rpy="0 0 0" xyz="-0.15 0 0" />
    <parent link="base_link" />
    <child link="back_bracket" />
  </joint>

  <joint name="base_front_bracket" type="fixed">
    <origin rpy="0 0 0" xyz="0.15 0 0" />
    <parent link="base_link" />
    <child link="front_bracket" />
  </joint>

  <!-- Front Left Leg -->
  <!-- m to mm -->
  <link name="front_left_hip">
    <visual>
      <origin rpy="0 0 1.57079632679" xyz="0 0.01 -0.015" />
      <geometry>
        <box size="0.05 0.05 0.06" />
      </geometry>
      <material name="orange" />
    </visual>
    <collision>
      <origin rpy="0 0 1.57079632679" xyz="0 0.01 -0.015" />
      <geometry>
        <box size="0.05 0.05 0.06" />
      </geometry>
    </collision>
    <inertial>
      <mass value="0.2" />
      <origin rpy="0 0 0" xyz="0 0 0" />
      <!-- Inertial Axes -->
      <inertia ixx="0.000140833333333" ixy="0" ixz="0" iyx="0" iyy="0.000112083333333" iyz="0" izx="0" izy="0" izz="0.000112083333333" />
    </inertial>
  </link>

  <joint name="motor_front_left_hip" type="revolute">
    <axis xyz="1 0 0" />
    <!-- 0.02 0.07 -->
    <!-- <origin rpy="0 0 0" xyz="0 0.07 -0.02" /> -->
    <origin rpy="0 0 0" xyz="0 0.06 -0.005" />
    <parent link="front_bracket" />
    <child link="front_left_hip" />
    <limit effort="1000.0" lower="-1.04" upper="1.04" velocity="0.7" />
    <joint_properties damping="0.0" friction="0.0" />
  </joint>

  <link name="front_left_upper_leg">
    <visual>
      <!-- <origin rpy="0 0 1.57079632679" xyz="0.005 0 -0.02" /> -->
      <origin rpy="0 0 1.57079632679" xyz="0.005 0 -0.06" />
      <geometry>
        <!-- <box size="0.07 0.06 0.09" /> -->
        <box size="0.07 0.06 0.16" />
      </geometry>
      <material name="black" />
    </visual>
    <collision>
      <origin rpy="0 0 1.57079632679" xyz="0.005 0 -0.02" />
      <geometry>
        <!-- prevent link collision  -->
        <box size="0.07 0.06 0.09" />
      </geometry>
    </collision>
    <inertial>
      <mass value="0.13" />
      <origin rpy="0 0 0" xyz="0 0 0" />
      <!-- Inertial Axes -->
      <inertia ixx="0.000144354166667" ixy="0" ixz="0" iyx="0" iyy="0.000144354166667" iyz="0" izx="0" izy="0" izz="2.65416666667e-05" />
    </inertial>
  </link>

  <joint name="motor_front_left_upper_leg" type="revolute">
    <axis xyz="0 1 0" />
    <!-- <origin rpy="0 0 0" xyz="0 0.07 -0.01" /> -->
    <origin rpy="0 0 0" xyz="0 0.07 -0.01" />
    <parent link="front_left_hip" />
    <child link="front_left_upper_leg" />
    <limit effort="1000.0" lower="-1.57079632679" upper="2.59" velocity="0.7" />
    <joint_properties damping="0.0" friction="0.0" />
  </joint>

  <link name="front_left_lower_leg">
    <visual>
      <origin rpy="0 0 1.57079632679" xyz="0 0 -0.055" />
      <geometry>
        <box size="0.04 0.04 0.16" />
      </geometry>
      <material name="black" />
    </visual>
    <collision>
      <origin rpy="0 0 1.57079632679" xyz="0 0 -0.055" />
      <geometry>
        <box size="0.04 0.04 0.16" />
      </geometry>
    </collision>
    <inertial>
      <mass value="0.05" />
      <origin rpy="0 0 0" xyz="0 0 0" />
      <!-- Inertial Axes -->
      <inertia ixx="6.51041666667e-05" ixy="0" ixz="0" iyx="0" iyy="6.51041666667e-05" iyz="0" izx="0" izy="0" izz="1.02083333333e-05" />
    </inertial>
  </link>

  <joint name="motor_front_left_lower_leg" type="revolute">
    <axis xyz="0 1 0" />
    <origin rpy="0 0 0" xyz="0.02 0 -0.12" />
    <parent link="front_left_upper_leg" />
    <child link="front_left_lower_leg" />
    <limit effort="1000.0" lower="-2.9" upper="1.57079632679" velocity="0.7" />
    <joint_properties damping="0.0" friction="0.0" />
  </joint>

  <link name="front_left_foot">
    <visual>
      <origin rpy="0 0 1.57079632679" xyz="0 0 0" />
      <geometry>
        <sphere radius="0.015" />
      </geometry>
      <material name="orange" />
    </visual>
    <collision>
      <origin rpy="0 0 1.57079632679" xyz="0 0 0" />
      <geometry>
        <sphere radius="0.015" />
      </geometry>
      <contact_coefficients mu="10.1" />
    </collision>
    <inertial>
      <mass value="0.005" />
      <origin rpy="0 0 0" xyz="0 0 0" />
      <!-- Inertial Axes -->
      <inertia ixx="3.52083333333e-06" ixy="0" ixz="0" iyx="0" iyy="2.80208333333e-06" iyz="0" izx="0" izy="0" izz="2.80208333333e-06" />
    </inertial>
  </link>

  <joint name="front_left_leg_foot" type="fixed">
    <origin rpy="0 0 0" xyz="0 0 -0.135" />
    <parent link="front_left_lower_leg" />
    <child link="front_left_foot" />
  </joint>

  <!-- Front Right Leg -->
  <link name="front_right_hip">
    <visual>
      <origin rpy="0 0 1.57079632679" xyz="0 -0.01 -0.015" />
      <geometry>
        <box size="0.05 0.05 0.06" />
      </geometry>
      <material name="orange" />
    </visual>
    <collision>
      <origin rpy="0 0 1.57079632679" xyz="0 0.01 -0.015" />
      <geometry>
        <box size="0.05 0.05 0.06" />
      </geometry>
    </collision>
    <inertial>
      <mass value="0.2" />
      <origin rpy="0 0 0" xyz="0 0 0" />
      <!-- Inertial Axes -->
      <inertia ixx="0.000140833333333" ixy="0" ixz="0" iyx="0" iyy="0.000112083333333" iyz="0" izx="0" izy="0" izz="0.000112083333333" />
    </inertial>
  </link>

  <joint name="motor_front_right_hip" type="revolute">
    <axis xyz="1 0 0" />
    <!-- 0.02 0.07 -->
    <!-- <origin rpy="0 0 0" xyz="0 0.07 -0.02" /> -->
    <origin rpy="0 0 0" xyz="0 -0.06 -0.005" />
    <parent link="front_bracket" />
    <child link="front_right_hip" />
    <limit effort="1000.0" lower="-1.04" upper="1.04" velocity="0.7" />
    <joint_properties damping="0.0" friction="0.0" />
  </joint>

  <link name="front_right_upper_leg">
    <visual>
      <origin rpy="0 0 1.57079632679" xyz="0.005 0 -0.06" />
      <geometry>
        <!-- <box size="0.07 0.06 0.16" /> -->
        <box size="0.07 0.06 0.16" />
      </geometry>
      <material name="black" />
    </visual>
    <collision>
      <origin rpy="0 0 1.57079632679" xyz="0.005 0 -0.02" />
      <geometry>
        <!-- prevent link collision  -->
        <box size="0.07 0.06 0.09" />
      </geometry>
    </collision>
    <inertial>
      <mass value="0.13" />
      <origin rpy="0 0 0" xyz="0 0 0" />
      <!-- Inertial Axes -->
      <inertia ixx="0.000144354166667" ixy="0" ixz="0" iyx="0" iyy="0.000144354166667" iyz="0" izx="0" izy="0" izz="2.65416666667e-05" />
    </inertial>
  </link>

  <joint name="motor_front_right_upper_leg" type="revolute">
    <axis xyz="0 1 0" />
    <origin rpy="0 0 0" xyz="0 -0.07 -0.01" />
    <parent link="front_right_hip" />
    <child link="front_right_upper_leg" />
    <limit effort="1000.0" lower="-1.57079632679" upper="2.59" velocity="0.7" />
    <joint_properties damping="0.0" friction="0.0" />
  </joint>

  <link name="front_right_lower_leg">
    <visual>
      <origin rpy="0 0 1.57079632679" xyz="0 0 -0.055" />
      <geometry>
        <box size="0.04 0.04 0.16" />
      </geometry>
      <material name="black" />
    </visual>
    <collision>
      <origin rpy="0 0 1.57079632679" xyz="0 0 -0.055" />
      <geometry>
        <box size="0.04 0.04 0.16" />
      </geometry>
    </collision>
    <inertial>
      <mass value="0.05" />
      <origin rpy="0 0 0" xyz="0 0 0" />
      <!-- Inertial Axes -->
      <inertia ixx="6.51041666667e-05" ixy="0" ixz="0" iyx="0" iyy="6.51041666667e-05" iyz="0" izx="0" izy="0" izz="1.02083333333e-05" />
    </inertial>
  </link>

  <joint name="motor_front_right_lower_leg" type="revolute">
    <axis xyz="0 1 0" />
    <origin rpy="0 0 0" xyz="0.02 0 -0.12" />
    <parent link="front_right_upper_leg" />
    <child link="front_right_lower_leg" />
    <limit effort="1000.0" lower="-2.9" upper="1.57079632679" velocity="0.7" />
    <joint_properties damping="0.0" friction="0.0" />
  </joint>

  <link name="front_right_foot">
    <visual>
      <origin rpy="0 0 1.57079632679" xyz="0 0 0" />
      <geometry>
        <sphere radius="0.015" />
      </geometry>
      <material name="orange" />
    </visual>
    <collision>
      <origin rpy="0 0 1.57079632679" xyz="0 0 0" />
      <geometry>
        <sphere radius="0.015" />
      </geometry>
      <contact_coefficients mu="10.1" />
    </collision>
    <inertial>
      <mass value="0.005" />
      <origin rpy="0 0 0" xyz="0 0 0" />
      <!-- Inertial Axes -->
      <inertia ixx="3.52083333333e-06" ixy="0" ixz="0" iyx="0" iyy="2.80208333333e-06" iyz="0" izx="0" izy="0" izz="2.80208333333e-06" />
    </inertial>
  </link>

  <joint name="front_right_leg_foot" type="fixed">
    <origin rpy="0 0 0" xyz="0 0 -0.135" />
    <parent link="front_right_lower_leg" />
    <child link="front_right_foot" />
  </joint>

  <!-- Back Left Leg -->
  <link name="back_left_hip">
    <visual>
      <origin rpy="0 0 1.57079632679" xyz="0 0.01 -0.015" />
      <geometry>
        <box size="0.05 0.05 0.06" />
      </geometry>
      <material name="orange" />
    </visual>
    <collision>
      <origin rpy="0 0 1.57079632679" xyz="0 0.01 -0.015" />
      <geometry>
        <box size="0.05 0.05 0.06" />
      </geometry>
    </collision>
    <inertial>
      <mass value="0.2" />
      <origin rpy="0 0 0" xyz="0 0 0" />
      <!-- Inertial Axes -->
      <inertia ixx="0.000140833333333" ixy="0" ixz="0" iyx="0" iyy="0.000112083333333" iyz="0" izx="0" izy="0" izz="0.000112083333333" />
    </inertial>
  </link>

  <joint name="motor_back_left_hip" type="revolute">
    <axis xyz="1 0 0" />
    <!-- 0.02 0.07 -->
    <!-- <origin rpy="0 0 0" xyz="0 0.07 -0.02" /> -->
    <origin rpy="0 0 0" xyz="0 0.06 -0.005" />
    <parent link="back_bracket" />
    <child link="back_left_hip" />
    <limit effort="1000.0" lower="-1.04" upper="1.04" velocity="0.7" />
    <joint_properties damping="0.0" friction="0.0" />
  </joint>

  <link name="back_left_upper_leg">
    <visual>
      <!-- <origin rpy="0 0 1.57079632679" xyz="0.005 0 -0.02" /> -->
      <origin rpy="0 0 1.57079632679" xyz="0.005 0 -0.06" />
      <geometry>
        <!-- <box size="0.07 0.06 0.09" /> -->
        <box size="0.07 0.06 0.16" />
      </geometry>
      <material name="black" />
    </visual>
    <collision>
      <origin rpy="0 0 1.57079632679" xyz="0.005 0 -0.02" />
      <geometry>
        <!-- prevent link collision  -->
        <box size="0.07 0.06 0.09" />
      </geometry>
    </collision>
    <inertial>
      <mass value="0.13" />
      <origin rpy="0 0 0" xyz="0 0 0" />
      <!-- Inertial Axes -->
      <inertia ixx="0.000144354166667" ixy="0" ixz="0" iyx="0" iyy="0.000144354166667" iyz="0" izx="0" izy="0" izz="2.65416666667e-05" />
    </inertial>
  </link>

  <joint name="motor_back_left_upper_leg" type="revolute">
    <axis xyz="0 1 0" />
    <origin rpy="0 0 0" xyz="0 0.07 -0.01" />
    <parent link="back_left_hip" />
    <child link="back_left_upper_leg" />
    <limit effort="1000.0" lower="-1.57079632679" upper="2.59" velocity="0.7" />
    <joint_properties damping="0.0" friction="0.0" />
  </joint>

  <link name="back_left_lower_leg">
    <visual>
      <origin rpy="0 0 1.57079632679" xyz="0 0 -0.055" />
      <geometry>
        <box size="0.04 0.04 0.16" />
      </geometry>
      <material name="black" />
    </visual>
    <collision>
      <origin rpy="0 0 1.57079632679" xyz="0 0 -0.055" />
      <geometry>
        <box size="0.04 0.04 0.16" />
      </geometry>
    </collision>
    <inertial>
      <mass value="0.05" />
      <origin rpy="0 0 0" xyz="0 0 0" />
      <!-- Inertial Axes -->
      <inertia ixx="6.51041666667e-05" ixy="0" ixz="0" iyx="0" iyy="6.51041666667e-05" iyz="0" izx="0" izy="0" izz="1.02083333333e-05" />
    </inertial>
  </link>

  <joint name="motor_back_left_lower_leg" type="revolute">
    <axis xyz="0 1 0" />
    <origin rpy="0 0 0" xyz="0.02 0 -0.12" />
    <parent link="back_left_upper_leg" />
    <child link="back_left_lower_leg" />
    <limit effort="1000.0" lower="-2.9" upper="1.57079632679" velocity="0.7" />
    <joint_properties damping="0.0" friction="0.0" />
  </joint>

  <link name="back_left_foot">
    <visual>
      <origin rpy="0 0 1.57079632679" xyz="0 0 0" />
      <geometry>
        <sphere radius="0.015" />
      </geometry>
      <material name="orange" />
    </visual>
    <collision>
      <origin rpy="0 0 1.57079632679" xyz="0 0 0" />
      <geometry>
        <sphere radius="0.015" />
      </geometry>
      <contact_coefficients mu="10.1" />
    </collision>
    <inertial>
      <mass value="0.005" />
      <origin rpy="0 0 0" xyz="0 0 0" />
      <!-- Inertial Axes -->
      <inertia ixx="3.52083333333e-06" ixy="0" ixz="0" iyx="0" iyy="2.80208333333e-06" iyz="0" izx="0" izy="0" izz="2.80208333333e-06" />
    </inertial>
  </link>

  <joint name="back_left_leg_foot" type="fixed">
    <origin rpy="0 0 0" xyz="0 0 -0.135" />
    <parent link="back_left_lower_leg" />
    <child link="back_left_foot" />
  </joint>

  <!-- Back Right Leg -->
  <link name="back_right_hip">
    <visual>
      <origin rpy="0 0 1.57079632679" xyz="0 -0.01 -0.015" />
      <geometry>
        <box size="0.05 0.05 0.06" />
      </geometry>
      <material name="orange" />
    </visual>
    <collision>
      <origin rpy="0 0 1.57079632679" xyz="0 0.01 -0.015" />
      <geometry>
        <box size="0.05 0.05 0.06" />
      </geometry>
    </collision>
    <inertial>
      <mass value="0.2" />
      <origin rpy="0 0 0" xyz="0 0 0" />
      <!-- Inertial Axes -->
      <inertia ixx="0.000140833333333" ixy="0" ixz="0" iyx="0" iyy="0.000112083333333" iyz="0" izx="0" izy="0" izz="0.000112083333333" />
    </inertial>
  </link>

  <joint name="motor_back_right_hip" type="revolute">
    <axis xyz="1 0 0" />
    <!-- 0.02 0.07 -->
    <!-- <origin rpy="0 0 0" xyz="0 0.07 -0.02" /> -->
    <origin rpy="0 0 0" xyz="0 -0.06 -0.005" />
    <parent link="back_bracket" />
    <child link="back_right_hip" />
    <limit effort="1000.0" lower="-1.04" upper="1.04" velocity="0.7" />
    <joint_properties damping="0.0" friction="0.0" />
  </joint>

  <link name="back_right_upper_leg">
    <visual>
      <origin rpy="0 0 1.57079632679" xyz="0.005 0 -0.06" />
      <geometry>
        <!-- <box size="0.07 0.06 0.16" /> -->
        <box size="0.07 0.06 0.16" />
      </geometry>
      <material name="black" />
    </visual>
    <collision>
      <origin rpy="0 0 1.57079632679" xyz="0.005 0 -0.02" />
      <geometry>
        <!-- prevent link collision  -->
        <box size="0.07 0.06 0.09" />
      </geometry>
    </collision>
    <inertial>
      <mass value="0.13" />
      <origin rpy="0 0 0" xyz="0 0 0" />
      <!-- Inertial Axes -->
      <inertia ixx="0.000144354166667" ixy="0" ixz="0" iyx="0" iyy="0.000144354166667" iyz="0" izx="0" izy="0" izz="2.65416666667e-05" />
    </inertial>
  </link>

  <joint name="motor_back_right_upper_leg" type="revolute">
    <axis xyz="0 1 0" />
    <origin rpy="0 0 0" xyz="0 -0.07 -0.01" />
    <parent link="back_right_hip" />
    <child link="back_right_upper_leg" />
    <limit effort="1000.0" lower="-1.57079632679" upper="2.59" velocity="0.7" />
    <joint_properties damping="0.0" friction="0.0" />
  </joint>

  <link name="back_right_lower_leg">
    <visual>
      <origin rpy="0 0 1.57079632679" xyz="0 0 -0.055" />
      <geometry>
        <box size="0.04 0.04 0.16" />
      </geometry>
      <material name="black" />
    </visual>
    <collision>
      <origin rpy="0 0 1.57079632679" xyz="0 0 -0.055" />
      <geometry>
        <box size="0.04 0.04 0.16" />
      </geometry>
    </collision>
    <inertial>
      <mass value="0.05" />
      <origin rpy="0 0 0" xyz="0 0 0" />
      <!-- Inertial Axes -->
      <inertia ixx="6.51041666667e-05" ixy="0" ixz="0" iyx="0" iyy="6.51041666667e-05" iyz="0" izx="0" izy="0" izz="1.02083333333e-05" />
    </inertial>
  </link>

  <joint name="motor_back_right_lower_leg" type="revolute">
    <axis xyz="0 1 0" />
    <origin rpy="0 0 0" xyz="0.02 0 -0.12" />
    <parent link="back_right_upper_leg" />
    <child link="back_right_lower_leg" />
    <limit effort="1000.0" lower="-2.9" upper="1.57079632679" velocity="0.7" />
    <joint_properties damping="0.0" friction="0.0" />
  </joint>

  <link name="back_right_foot">
    <visual>
      <origin rpy="0 0 1.57079632679" xyz="0 0 0" />
      <geometry>
        <sphere radius="0.015" />
      </geometry>
      <material name="orange" />
    </visual>
    <collision>
      <origin rpy="0 0 1.57079632679" xyz="0 0 0" />
      <geometry>
        <sphere radius="0.015" />
      </geometry>
      <contact_coefficients mu="10.1" />
    </collision>
    <inertial>
      <mass value="0.005" />
      <origin rpy="0 0 0" xyz="0 0 0" />
      <!-- Inertial Axes -->
      <inertia ixx="3.52083333333e-06" ixy="0" ixz="0" iyx="0" iyy="2.80208333333e-06" iyz="0" izx="0" izy="0" izz="2.80208333333e-06" />
    </inertial>
  </link>

  <joint name="back_right_leg_foot" type="fixed">
    <origin rpy="0 0 0" xyz="0 0 -0.135" />
    <parent link="back_right_lower_leg" />
    <child link="back_right_foot" />
  </joint>

</robot>